<?xml version="1.0" encoding="utf-8"?>

<mujoco model ="lumi">
    <include file="model.xml"/>
    <asset>
        <mesh file="frame_v5_leftpillar_back_bin.stl" name="frame_left"/>
        <mesh file="frame_v5_leftpillar_front_bin.stl" name="frame_left_front"/>
        <mesh file="frame_v5_rightpillar_bin.stl" name="frame_right"/>
        <mesh file="frame_v5_top_bottom_bin.stl" name="frame_top_bottom"/>
        <mesh file="door_v5_bin.stl" name="door"/>
        <mesh file="handle_v5_beam_bin.stl" name="handle_beam"/>
        <mesh file="handle_v5_latch_bin.stl" name="handle_latch"/>
        <mesh file="handle_v5_core_bin.stl" name="handle_core"/>
    </asset>
    <!--<option gravity="0 0 0"/>-->
    <compiler eulerseq="xyz" coordinate="local"/>
    <worldbody>
        <body pos="0.40 0.25 0.052" euler="0 0 -1.571">
        <inertial diaginertia="1 1 1" mass="0.05" pos="0 0 0"/>
            <body name="door" pos="0.005 0.005 0.005">
                <!--camera pos="0 0 0" mode="targetbody" target="handle_core"/-->
                <camera pos="0 0 0"/>
                <inertial diaginertia="1 1 1" mass="1.5" pos=".130 .027 .165"/>
                <joint type="hinge" axis="0 0 -1" armature="0.001" damping="0.001" range="0 1.571" pos=".262 .049 0" name="door_hinge" limited="true"/>
                <geom condim="3" type="mesh" mesh="door" rgba="1 0 0 1"/>
                <body name="handle_core" pos=".052 -.060 .095">
                    <inertial diaginertia="1 1 1" mass="0.2" pos="0 0 0"/>
                    <joint type="hinge" damping="0.001" armature="0.001" stiffness="1" axis="0 1 0" range="0 0.5236" pos="0 0 0" name="handle_core" limited="true"/>
                    <geom condim="1" type="mesh" mesh="handle_core" rgba="0 1 0 1"/>
                    <body name="handle_beam" pos=".015 0 -.0165">
                        <inertial diaginertia="1 1 1" mass="0.1" pos="0 .0165 0"/>
                        <geom name="beam" condim="6" type="mesh" mesh="handle_beam" rgba="0 1 0 1" friction="1 .005 .0001"/>
                    </body>
                    <body name="handle_latch" pos="-.015 .040 -.010">
                        <inertial diaginertia="1 1 1" mass="0.0000001" pos="0 0 .010"/>
                        <geom condim="1" type="mesh" mesh="handle_latch" rgba="0 1 0 1"/>
                    </body>
                </body>
            </body>
            <body name="frame_left" pos="-.025 .010 0">
                <inertial diaginertia="1 1 1" mass="100" pos="-.012 -.004 -.052"/>
                <geom condim="3" type="mesh" mesh="frame_left" rgba="0 0 1 1"/>
            </body>
            <body name="frame_left_front" pos="-.025 0 0">
                <inertial diaginertia="1 1 1" mass="100" pos="-.012 -.004 -.052"/>
                <geom condim="3" type="mesh" mesh="frame_left_front" rgba="0 0 1 1"/>
            </body>
            <body name="frame_right" pos=".267 0 0">
                <inertial diaginertia="1 1 1" mass="100" pos="-.012 -.004 -.052"/>
                <geom condim="3" type="mesh" mesh="frame_right" rgba="0 0 1 1"/>
            </body>
            <body name="frame_bottom" pos="-.025 0 -.052">
                <inertial diaginertia="1 1 1" mass="100" pos="-.012 -.004 -.052"/>
                <geom condim="3" type="mesh" mesh="frame_top_bottom" rgba="0 0 1 1"/>
            </body>
            <body name="frame_top" pos="-.025 0 .335">
                <inertial diaginertia="1 1 1" mass="100" pos="-.012 -.004 -.052"/>
                <geom condim="3" type="mesh" mesh="frame_top_bottom" rgba="0 0 1 1"/>
            </body>
        </body>    
    </worldbody>
    <!--<default>
    <default class="handle-robot">
            <pair condim="6" solref="0.004 1" solimp="0.30 0.99 0.004" friction="1 0.005 0.0001"/>
    </default>
</default>-->
    
    <contact>
        <pair geom1="beam" geom2="leftfinger" condim="6" solref="0.004 1" solimp="0.30 0.99 0.004" friction="1 0.005 0.0001"/>
        <pair geom1="beam" geom2="rightfinger" condim="6" solref="0.004 1" solimp="0.30 0.99 0.004" friction="1 0.005 0.0001"/>
    </contact>
    <actuator>
        <!-- <motor gear="10" joint="door_hinge" forcerange="0 20" forcelimited="true"/>
        <motor gear="10" joint="handle_core" forcerange="0 200" forcelimited="true"/> -->
        <motor gear="-1" joint="lumi_joint4"/>
        <motor gear="5" joint="lumi_joint2"/>
        <motor gear="1" joint="lumi_joint3"/>
        <motor gear="1" joint="lumi_joint6"/>
        <motor gear="0.1" joint="lumi_joint7"/>
        <motor gear="3.2" joint="lumi_joint2"/>
        <motor gear="0.5" joint="lumi_joint6"/>
        <motor gear="1" joint="lumi_finger_joint1"/>
        <motor gear="1" joint="lumi_finger_joint2"/>
    </actuator> 
</mujoco>


